<?xml version="1.0" ?>
<robot name="RP" xmlns:xacro="http://www.ros.org/wiki/xacro">

<xacro:include filename="$(find RP_description)/urdf/materials.xacro" />
<xacro:include filename="$(find RP_description)/urdf/RP.trans" />
<xacro:include filename="$(find RP_description)/urdf/RP.gazebo" />
<link name="base_link">
  <inertial>
    <origin xyz="3.019715383457247e-11 3.0286398058123193e-12 0.04300979484933489" rpy="0 0 0"/>
    <mass value="4.071597447876389"/>
    <inertia ixx="0.006647" iyy="0.00646" izz="0.007974" ixy="-0.0" iyz="0.0" ixz="0.0"/>
  </inertial>
  <visual>
    <origin xyz="0 0 0" rpy="0 0 0"/>
    <geometry>
      <mesh filename="package://RP_description/meshes/base_link.stl" scale="0.001 0.001 0.001"/>
    </geometry>
    <material name="silver"/>
  </visual>
  <collision>
    <origin xyz="0 0 0" rpy="0 0 0"/>
    <geometry>
      <mesh filename="package://RP_description/meshes/base_link.stl" scale="0.001 0.001 0.001"/>
    </geometry>
  </collision>
</link>

<link name="Componente5_1">
  <inertial>
    <origin xyz="-6.551741014804067e-15 0.0 -0.029302995324400033" rpy="0 0 0"/>
    <mass value="1.4329758168878506"/>
    <inertia ixx="0.00077" iyy="0.0009" izz="0.000718" ixy="-0.0" iyz="0.0" ixz="0.0"/>
  </inertial>
  <visual>
    <origin xyz="-0.0 -0.0 -0.07" rpy="0 0 0"/>
    <geometry>
      <mesh filename="package://RP_description/meshes/Componente5_1.stl" scale="0.001 0.001 0.001"/>
    </geometry>
    <material name="silver"/>
  </visual>
  <collision>
    <origin xyz="-0.0 -0.0 -0.07" rpy="0 0 0"/>
    <geometry>
      <mesh filename="package://RP_description/meshes/Componente5_1.stl" scale="0.001 0.001 0.001"/>
    </geometry>
  </collision>
</link>

<link name="q1_1">
  <inertial>
    <origin xyz="-0.004888834987006494 0.007815175841509137 0.017771527603799395" rpy="0 0 0"/>
    <mass value="0.4353288415386871"/>
    <inertia ixx="0.000191" iyy="0.000139" izz="0.00023" ixy="4.4e-05" iyz="-5.1e-05" ixz="2.6e-05"/>
  </inertial>
  <visual>
    <origin xyz="-0.0 -0.0 -0.09" rpy="0 0 0"/>
    <geometry>
      <mesh filename="package://RP_description/meshes/q1_1.stl" scale="0.001 0.001 0.001"/>
    </geometry>
    <material name="silver"/>
  </visual>
  <collision>
    <origin xyz="-0.0 -0.0 -0.09" rpy="0 0 0"/>
    <geometry>
      <mesh filename="package://RP_description/meshes/q1_1.stl" scale="0.001 0.001 0.001"/>
    </geometry>
  </collision>
</link>

<link name="q2_1">
  <inertial>
    <origin xyz="0.024670696257735675 0.17724582541173717 0.004030315334017848" rpy="0 0 0"/>
    <mass value="2.5737597722382"/>
    <inertia ixx="0.038349" iyy="0.000848" izz="0.038442" ixy="-0.000839" iyz="-0.000855" ixz="-1.9e-05"/>
  </inertial>
  <visual>
    <origin xyz="0.0045 -0.035737 -0.126223" rpy="0 0 0"/>
    <geometry>
      <mesh filename="package://RP_description/meshes/q2_1.stl" scale="0.001 0.001 0.001"/>
    </geometry>
    <material name="silver"/>
  </visual>
  <collision>
    <origin xyz="0.0045 -0.035737 -0.126223" rpy="0 0 0"/>
    <geometry>
      <mesh filename="package://RP_description/meshes/q2_1.stl" scale="0.001 0.001 0.001"/>
    </geometry>
  </collision>
</link>

<link name="q3_1">
  <inertial>
    <origin xyz="-0.026358942068685092 0.08182322407081788 -0.0004459995802148231" rpy="0 0 0"/>
    <mass value="1.1219211238898206"/>
    <inertia ixx="0.009906" iyy="0.00091" izz="0.010525" ixy="0.00184" iyz="-5.8e-05" ixz="-1.3e-05"/>
  </inertial>
  <visual>
    <origin xyz="-0.022 -0.425636 -0.135088" rpy="0 0 0"/>
    <geometry>
      <mesh filename="package://RP_description/meshes/q3_1.stl" scale="0.001 0.001 0.001"/>
    </geometry>
    <material name="silver"/>
  </visual>
  <collision>
    <origin xyz="-0.022 -0.425636 -0.135088" rpy="0 0 0"/>
    <geometry>
      <mesh filename="package://RP_description/meshes/q3_1.stl" scale="0.001 0.001 0.001"/>
    </geometry>
  </collision>
</link>

<link name="q4_1">
  <inertial>
    <origin xyz="-0.026001432271549732 0.19019234338225122 0.0020487608870461693" rpy="0 0 0"/>
    <mass value="2.3634814905972625"/>
    <inertia ixx="0.017319" iyy="0.00225" izz="0.017337" ixy="0.000179" iyz="-0.000328" ixz="2e-06"/>
  </inertial>
  <visual>
    <origin xyz="0.050722 -0.569744 -0.132001" rpy="0 0 0"/>
    <geometry>
      <mesh filename="package://RP_description/meshes/q4_1.stl" scale="0.001 0.001 0.001"/>
    </geometry>
    <material name="silver"/>
  </visual>
  <collision>
    <origin xyz="0.050722 -0.569744 -0.132001" rpy="0 0 0"/>
    <geometry>
      <mesh filename="package://RP_description/meshes/q4_1.stl" scale="0.001 0.001 0.001"/>
    </geometry>
  </collision>
</link>

<link name="q5_1">
  <inertial>
    <origin xyz="-3.724601281007711e-07 0.160373681832782 0.003646254303925789" rpy="0 0 0"/>
    <mass value="1.8115927533864018"/>
    <inertia ixx="0.012478" iyy="0.001149" izz="0.012472" ixy="-0.0" iyz="-0.000258" ixz="0.0"/>
  </inertial>
  <visual>
    <origin xyz="0.077121 -0.654774 -0.131624" rpy="0 0 0"/>
    <geometry>
      <mesh filename="package://RP_description/meshes/q5_1.stl" scale="0.001 0.001 0.001"/>
    </geometry>
    <material name="silver"/>
  </visual>
  <collision>
    <origin xyz="0.077121 -0.654774 -0.131624" rpy="0 0 0"/>
    <geometry>
      <mesh filename="package://RP_description/meshes/q5_1.stl" scale="0.001 0.001 0.001"/>
    </geometry>
  </collision>
</link>

<link name="q6_1">
  <inertial>
    <origin xyz="-3.7246012783709315e-07 0.04228440998289673 0.0009616177083263677" rpy="0 0 0"/>
    <mass value="1.5169719326279612"/>
    <inertia ixx="0.001216" iyy="0.001084" izz="0.00129" ixy="0.0" iyz="-5e-06" ixz="-7e-06"/>
  </inertial>
  <visual>
    <origin xyz="0.077121 -0.924705 -0.137761" rpy="0 0 0"/>
    <geometry>
      <mesh filename="package://RP_description/meshes/q6_1.stl" scale="0.001 0.001 0.001"/>
    </geometry>
    <material name="silver"/>
  </visual>
  <collision>
    <origin xyz="0.077121 -0.924705 -0.137761" rpy="0 0 0"/>
    <geometry>
      <mesh filename="package://RP_description/meshes/q6_1.stl" scale="0.001 0.001 0.001"/>
    </geometry>
  </collision>
</link>

<joint name="Rígida1" type="fixed">
  <origin xyz="0.0 0.0 0.07" rpy="0 0 0"/>
  <parent link="base_link"/>
  <child link="Componente5_1"/>
</joint>

<joint name="Revolución2" type="revolute">
  <origin xyz="0.0 0.0 0.02" rpy="0 0 0"/>
  <parent link="Componente5_1"/>
  <child link="q1_1"/>
  <axis xyz="0.0 0.0 1.0"/>
  <limit upper="6.283185" lower="0.0" effort="100" velocity="100"/>
</joint>

<joint name="Revolución3" type="revolute">
  <origin xyz="-0.0045 0.035737 0.036223" rpy="0 0 0"/>
  <parent link="q1_1"/>
  <child link="q2_1"/>
  <axis xyz="1.0 0.0 0.0"/>
  <limit upper="3.141593" lower="0.0" effort="100" velocity="100"/>
</joint>

<joint name="Revolución4" type="revolute">
  <origin xyz="0.0265 0.389899 0.008865" rpy="0 0 0"/>
  <parent link="q2_1"/>
  <child link="q3_1"/>
  <axis xyz="-0.0 -0.999742 -0.022731"/>
  <limit upper="6.283185" lower="0.0" effort="100" velocity="100"/>
</joint>

<joint name="Revolución5" type="revolute">
  <origin xyz="-0.072722 0.144108 -0.003087" rpy="0 0 0"/>
  <parent link="q3_1"/>
  <child link="q4_1"/>
  <axis xyz="-0.996195 0.001981 -0.087133"/>
  <limit upper="6.283185" lower="0.0" effort="100" velocity="100"/>
</joint>

<joint name="Corredera6" type="prismatic">
  <origin xyz="-0.026399 0.08503 -0.000377" rpy="0 0 0"/>
  <parent link="q4_1"/>
  <child link="q5_1"/>
  <axis xyz="0.0 0.999742 0.022731"/>
  <limit upper="0.24" lower="0.0" effort="100" velocity="100"/>
</joint>

<joint name="Revolución7" type="revolute">
  <origin xyz="0.0 0.269931 0.006137" rpy="0 0 0"/>
  <parent link="q5_1"/>
  <child link="q6_1"/>
  <axis xyz="-0.0 -0.999742 -0.022731"/>
  <limit upper="6.283185" lower="0.0" effort="100" velocity="100"/>
</joint>

</robot>
